Workbook
Name 会社保険率: 'テーブル定義-社会'!$B$95
Name 健康・介護保険料額: 'テーブル定義-社会'!$B$136
Name 雇用保険料額: 'テーブル定義-社会'!$B$502
Name 厚生年金料額: 'テーブル定義-社会'!$B$227
Name 事業所整理記号情報: 'テーブル定義-社会'!$B$442
Name 退職金計算項目: 'テーブル定義-社会'!$B$667
Name 退職金計算書設定: 'テーブル定義-社会'!$B$704
Name 退職金計算書設定詳細: 'テーブル定義-社会'!$B$729
Name 退職金項目: 'テーブル定義-社会'!$B$624
Name 退職金体系: 'テーブル定義-社会'!$B$592
Name 退職金明細書設定: 'テーブル定義-社会'!$B$766
Name 退職金明細書設定詳細: 'テーブル定義-社会'!$B$791
Name 届出基本: 'テーブル定義-社会'!$C$333

Sheet 表紙
A2: データベース定義書
B4: ユーザー | C4: 株式会社エフエム
B5: プロジェクト | C5: SociaX
B6: インスタンス | C6: テナント別
B7: システム | C7: 給与管理
B11: 作成日 | C11: 46008
B12: 作成者 | C12: ISI王
B13: 更新日 | C13: =改定履歴!J5 -> 46008
B14: 更新者 | C14: =改定履歴!K5 -> ISI王
D16: ©株式会社エフエム

Sheet 表定義の見直しについて
A1: =表紙!A2 -> データベース定義書 | C1: 表定義の見直しについて | I1: 版 | J1: 年月日 | K1: 作成/更新者
A2: =表紙!B4 -> ユーザー | B2: =表紙!C4 -> 株式会社エフエム | I2: 初 | J2: =表紙!C11 -> 46008 | K2: =表紙!C12 -> ISI王
A3: =表紙!B5 -> プロジェクト | B3: =表紙!C5 -> SociaX
A4: =表紙!B6 -> インスタンス | B4: =表紙!C6 -> テナント別
A5: =表紙!B7 -> システム | B5: =表紙!C7 -> 給与管理 | I5: 最終
A7: チケットNo. | C7: 改訂内容 | I7: 版 | J7: 改訂日付 | K7: 改訂者
A8: #220435 | C8: 社員管理の表は以下チケットを起点に見直しを行っています
C9: #218603 テーブル・カラム名 全面見直し
D10: 資料
E11: #218603 テーブル・カラム名 全面見直し - 資料.xlsx
E12: #218603 テーブル・カラム名 全面見直し - 資料.pptx
D14: テーブル名の見直し
E15: 主な修正点
F16: 表名自体の最適化
H17: 慣習性が高い語句を含め、データとして格納される内容を端的に表現できるようにします
F18: 日本語のローマ字表記を廃止
H19: 但し、旧Sociaで慣習性が高い以下のキーワードは日本語として残している
H20: 会社 kaisya
H21: 社員 syain
H22: など
F23: プレフィックスの廃止
D25: 列名の見直し
E26: 主な修正点
F27: 日本語のローマ字表記を廃止
H28: 但し、旧Sociaで慣習性が高い以下のキーワードは日本語として残している
H29: 社員連番 syainseq
H30: 会社コード kaisyacd
H31: など
D33: テーブル定義の見直し
E34: データの構成は一度精査し、非正規化への戻しも含めデータ構造のバランスを取りながらテーブル定義を再編します
D36: 本稼働が行われるまでは修正内容が確認できるようにします
H37: 可能な限り旧定義を残して、修正、削除などが行われたことがわかるようにしておく
A39: #220435 | B39: 共通 | D39: ナチュラルキーとサロゲートキーの分け方 | J39: 45616 | K39: CSM栗原
E40: ナチュラルキー
H41: キーそのものに業務的な意味が含まれており、意図的にユニークに定義されているもの。エンドユーザー側で定義される
H42: 例) 会社コード、組織コード、郵便番号、社員番号(本来は)
E43: サロゲートキー
H44: 業務的は意味を持つ値ではなく、システム上ユニークになるように連番が設定されるもの
H45: 例) 社員連番、性別ID(ないけど)、家族の連番(並び順は別)
E46: Sociaではエンドユーザーが定義するケースが多いナチュラルキーを優先して使用します
...

Sheet 論理データモデル
A1: =表紙!A2 -> データベース定義書 | C1: 論理データモデル | E1: 版 | F1: 年月日 | G1: 作成/更新者
A2: =表紙!B4 -> ユーザー | B2: =表紙!C4 -> 株式会社エフエム | E2: 初 | F2: =表紙!C11 -> 46008 | G2: =表紙!C12 -> ISI王
A3: =表紙!B5 -> プロジェクト | B3: =表紙!C5 -> SociaX
A4: =表紙!B6 -> インスタンス | B4: =表紙!C6 -> テナント別
A5: =表紙!B7 -> システム | B5: =表紙!C7 -> 給与管理 | E5: 最終 | F5: =表紙!C13 -> 46008 | G5: =表紙!C14 -> ISI王

Sheet 改定履歴
A1: =表紙!A2 -> データベース定義書 | C1: 改訂履歴 | I1: 版 | J1: 年月日 | K1: 作成/更新者
A2: =表紙!B4 -> ユーザー | B2: =表紙!C4 -> 株式会社エフエム | I2: 初 | J2: =表紙!C11 -> 46008 | K2: =表紙!C12 -> ISI王
A3: =表紙!B5 -> プロジェクト | B3: =表紙!C5 -> SociaX
A4: =表紙!B6 -> インスタンス | B4: =表紙!C6 -> テナント別
A5: =表紙!B7 -> システム | B5: =表紙!C7 -> 給与管理 | I5: 最終 | J5: =MAX($J$8:$J$925) -> 46008 | K5: =VLOOKUP(J5,$J$8:$K$925,2,FALSE) -> ISI王
A7: チケットNo. | B7: シート名 | C7: 改訂内容 | I7: 版 | J7: 改訂日付 | K7: 改訂者
A8: #220435 | B8: 全体 | C8: 初版 | F8: 作成開始。表紙とテーブル一覧の作成 | J8: 46008 | K8: ISI王

Sheet 退職金支給 (2)
A1: テーブル情報
B2: システム名 | C2: SOCIA | E2: 作成者 | I2: ITSP | M2: テーブル一覧へ
B3: サブシステム名 | C3: 給与 | E3: 作成日 | I3: 2025-11-28
B4: スキーマ名 | E4: RDBMS | I4: MySQL
B5: 論理テーブル名 | C5: 退職金支給 | E5: ENGINE | I5: InnoDB
B6: 物理テーブル名 | C6: retirement_pay_payment | E6: CHARSET | I6: utf8mb4
B7: 備考
A12: カラム情報 | L12: 外部キー情報
A13: No | B13: 論理名 | C13: 物理名 | D13: データ型 | E13: Size | F13: Not Null | G13: PK | H13: UK | I13: デフォルト | J13: 備考 | L13: 親テーブル | M13: 参照カラム
A14: 1 | B14: 社員連番 | C14: syainseq | D14: bigint | F14: not null | G14: 〇
A15: 2 | B15: 退職年月日 | C15: retirement_date | D15: date | F15: not null | G15: 〇
A16: 3 | B16: 社員コード | C16: syaincd | D16: varchar | E16: 20
A17: 4 | B17: 氏名 | C17: name | D17: varchar | E17: 255
A18: 5 | B18: 支給確定年月日 | C18: payment_confirm_date | D18: date | F18: not null
A19: 6 | B19: 支給年月日 | C19: payment_date | D19: date
A20: 7 | B20: 勤続期間開始年月日 | C20: tenure_period_fromymd | D20: date | F20: not null
A21: 8 | B21: 勤続期間終了年月日 | C21: tenure_period_toymd | D21: date | F21: not null
A22: 9 | B22: 勤続年数 | C22: tenure_year_count | D22: tinyint | F22: not null
A23: 10 | B23: 退職一時金区分 | C23: retirement_temporary_amount_type | D23: tinyint | F23: not null
A24: 11 | B24: 退職一時金額 | C24: retirement_temporary_amount | D24: bigint | F24: not null
A25: 12 | B25: 退職所得控除額 | C25: retirement_income_deduction_amount | D25: bigint | F25: not null
A26: 13 | B26: 源泉徴収税額 | C26: withholding_tax_amount | D26: bigint | F26: not null
A27: 14 | B27: 市町村民税額 | C27: municipalities_resident_tax | D27: bigint | F27: not null
A28: 15 | B28: 道府県民税額 | C28: prefecture_resident_tax | D28: bigint | F28: not null
A29: 16 | B29: 住民税清算額 | C29: resident_tax_settlement_amount | D29: bigint
A30: 17 | B30: 申告書提出区分 | C30: tax_return_filing_type | D30: tinyint | F30: not null
A31: 18 | B31: 障害退職区分 | C31: disability_retirement_type | D31: tinyint | F31: not null
A32: 19 | B32: 税計算区分 | C32: tax_equation_type | D32: tinyint | F32: not null
A33: 20 | B33: 源泉徴収税区分 | C33: withholding_tax_type | D33: tinyint | F33: not null
A34: 21 | B34: 源泉徴収摘要欄 | C34: withholding_summary_ran | D34: varchar | E34: 100
A35: 22 | B35: 差引支給額 | C35: deduct_payment_amount | D35: bigint | F35: not null
A36: 23 | B36: 特定役員 | C36: specific_officer | D36: tinyint | F36: not null
A37: 24 | B37: 作成者 | C37: created_by | D37: bigint | F37: not null
A38: 25 | B38: 作成日時 | C38: created_at | D38: datetime | E38: 6 | F38: not null
A39: 26 | B39: 更新者 | C39: updated_by | D39: bigint | F39: not null
A40: 27 | B40: 更新日時 | C40: updated_at | D40: datetime | E40: 6 | F40: not null

Sheet テーブル一覧ISI
A1: =表紙!A2 -> データベース定義書 | C1: テーブル一覧 | E1: 版 | F1: 年月日 | G1: 作成/更新者
A2: =表紙!B4 -> ユーザー | B2: =表紙!C4 -> 株式会社エフエム | E2: 初 | F2: =表紙!C11 -> 46008 | G2: =表紙!C12 -> ISI王
A3: =表紙!B5 -> プロジェクト | B3: =表紙!C5 -> SociaX
A4: =表紙!B6 -> インスタンス | B4: =表紙!C6 -> テナント別
A5: =表紙!B7 -> システム | B5: =表紙!C7 -> 給与管理 | E5: 最終 | F5: =表紙!C13 -> 46008 | G5: =表紙!C14 -> ISI王
A7: 社会
A8: No. | B8: 論理テーブル名 | C8: 物理テーブル名 | D8: 備考 | F8: 改訂日付 | G8: 改訂者
A9: 1 | B9: 健康・介護保険料額パターン | C9: health_care_insurance_amount_pattern | F9: 46054 | G9: ISI王
A10: =A9+1 -> 2 | B10: 健康・介護保険料額 | C10: health_care_insurance_amount | F10: 46008 | G10: ISI王
A11: =A10+1 -> 3 | B11: 厚生年金料額パターン | C11: kosei_pension_amount_pattern
A12: =A11+1 -> 4 | B12: 厚生年金料額 | C12: kosei_pension_amount
A13: =A12+1 -> 5 | B13: 届出基本 | C13: submission_basic | F13: 46019 | G13: ISI王
A14: =A13+1 -> 6 | B14: 健康・介護保険料額 | C14: health_care_insurance_amount | F14: 46008 | G14: ISI王
A15: =A14+1 -> 7 | B15: 事業所整理記号情報 | C15: office_arrangement_mark_info | F15: 46009 | G15: ISI王
A16: =A15+1 -> 8 | B16: 会社保険率 | C16: kaisya_insurance_rate | F16: 46009 | G16: ISI王
A17: =A16+1 -> 9 | B17: 厚生年金料額 | C17: kosei_pension_amount | F17: 46019 | G17: ISI王
A18: =A17+1 -> 10 | B18: 雇用保険料額 | C18: employment_insurance_amount | F18: 46019 | G18: ISI王
A19: =A18+1 -> 11 | B19: 労災保険料率 | C19: employment_insurance_amount | F19: 46040 | G19: ISI王
A20: =A19+1 -> 12 | B20: 退職金体系 | C20: retirement_taikei | F20: 46034 | G20: ISI王
A21: =A20+1 -> 13 | B21: 退職金項目 | C21: retirement_item | F21: 46034 | G21: ISI王
A22: =A21+1 -> 14 | B22: 退職金計算項目 | C22: retirement_calc_item | F22: 46040 | G22: ISI王
A23: =A22+1 -> 15 | B23: 退職金計算書 | C23: retirement_calc_statement | F23: 46040 | G23: ISI王
A24: =A23+1 -> 16 | B24: 退職金計算書詳細 | C24: retirement_calc_statement_detail | F24: 46040 | G24: ISI王
... A26: =A25+1 -> 18 | B26: 退職金明細書詳細 | C26: retirement_calc_detail_statement_detail | F26: 46040 | G26: ISI王
A27: =A26+1 -> 19
A28: =A27+1 -> 20

Sheet テーブル定義-社会
A1: =表紙!A2 -> データベース定義書 | D1: テーブル定義 | N1: 更新情報
A2: =表紙!B4 -> ユーザー | C2: =表紙!C4 -> 株式会社エフエム | N2: ="作成:"&TEXT(表紙!C11,"yyyy/mm/dd")&" "&表紙!C12 -> 作成:2025/12/17 ISI王
A3: =表紙!B5 -> プロジェクト | C3: =表紙!C5 -> SociaX
A4: =表紙!B6 -> インスタンス | C4: =表紙!C6 -> テナント別
A5: =表紙!B7 -> システム | C5: =表紙!C7 -> 給与管理 | N5: ="更新:"&TEXT(表紙!C13,"yyyy/mm/dd")&" "&表紙!C14 -> 更新:2025/12/17 ISI王
A7: No. | B7: 論理テーブル名 | C7: 物理テーブル名 | D7: 説明
A8: 14 | B8: 給与会社マスタ | C8: kyuyo_kaisya_master
B9: RDBMS | C9: MySQL
B10: ENGINE | C10: InnoDB
B11: CHARSET | C11: utf8mb4
B13: 作成日 / 作成者 | C13: 2026/01/18 王
B14: 更新日 / 更新者
A16: No, | B16: 論理名 | C16: 物理名 | D16: データ型 | E16: サイズ | F16: NOT NULL | G16: PK | H16: UK | I16: 索引123 | L16: デフォルト | M16: 関連/参照キー | N16: 列とコードの説明 / 備考
A17: 1 | B17: 会社コード | C17: kaisyacd | D17: varchar | E17: 10 | F17: not null | G17: 〇
A18: =A17+1 -> 2 | B18: 有効開始年月日 | C18: fromymd | D18: date | F18: not null | G18: 〇
A19: =A18+1 -> 3 | B19: 有効終了年月日 | C19: toymd | D19: date | F19: not null
A20: =A19+1 -> 4 | B20: 項目区分 | C20: item_type | D20: tinyint | F20: not null | N20: 1:全般 2:届出の管理 3:情報公開設定 4:計算区分 5:社会保険(共通) 6:健保料率パターン 7:厚年料率パターン 8:労災料率パターン 9:代表者パターン 10:連絡者パターン 11:金融機関パターン
A21: =A20+1 -> 5 | B21: 定年年齢 | C21: retirement_age | D21: smallint
A22: =A21+1 -> 6 | B22: 届出の利用 | C22: use_submission | D22: boolean | N22: true:利用する false:利用しない
A23: =A22+1 -> 7 | B23: 届出許可項目設定区分 | C23: submission_authorized Item_type | D23: tinyint | N23: 1:すべて許可 2:限定する
A24: =A23+1 -> 8 | B24: 届出許可項目設定格納値JSON | C24: submission_authorized Item_store_json | D24: json
A25: =A24+1 -> 9 | B25: 給与支給明細書・設定区分 | C25: kyuyo_pay_slip_use_type | D25: tinyint | N25: 1:既定値 2:届出内共通
A26: =A25+1 -> 10 | B26: 給与支給明細書・支給日前公開日数 | C26: kyuyo_pay_slip_before_pay_open_days | D26: smallint
A27: =A26+1 -> 11 | B27: 給与支給明細書・公開除外日 | C27: kyuyo_pay_slip_excluded_days | D27: json | N27: {["name":"月","value":0/1], ["name":"火","value":0/1], ["name":"水","value":0/1], ["name":"木","value":0/1], ["name":"金","value":0/1], ["name":"土","value":0/1], ["name":"日","value":0/1], ["name":"祝","value":0/1]}
A28: =A27+1 -> 12 | B28: 賞与支給明細書・設定区分 | C28: syoyo_pay_slip_use_type | D28: tinyint | N28: 1:既定値 2:届出内共通
A29: =A28+1 -> 13 | B29: 賞与支給明細書・支給日前公開日数 | C29: syoyo_pay_slip_before_pay_open_days | D29: smallint
A30: =A29+1 -> 14 | B30: 賞与支給明細書・公開除外日 | C30: syoyo_pay_slip_excluded_days | D30: json | N30: {["name":"月","value":0/1], ["name":"火","value":0/1], ["name":"水","value":0/1], ["name":"木","value":0/1], ["name":"金","value":0/1], ["name":"土","value":0/1], ["name":"日","value":0/1], ["name":"祝","value":0/1]}
A31: =A30+1 -> 15 | B31: 臨時給与支給明細書・設定区分 | C31: rinji_pay_slip_use_type | D31: tinyint | N31: 1:既定値 2:届出内共通
A32: =A31+1 -> 16 | B32: 臨時給与支給明細書・支給日前公開日数 | C32: rinji_pay_slip_before_pay_open_days | D32: smallint
A33: =A32+1 -> 17 | B33: 臨時給与支給明細書・公開除外日 | C33: rinji_pay_slip_excluded_days | D33: json | N33: {["name":"月","value":0/1], ["name":"火","value":0/1], ["name":"水","value":0/1], ["name":"木","value":0/1], ["name":"金","value":0/1], ["name":"土","value":0/1], ["name":"日","value":0/1], ["name":"祝","value":0/1]}
A34: =A33+1 -> 18 | B34: 退職金支給明細書・設定区分 | C34: retirement_pay_slip_use_type | D34: tinyint | N34: 1:既定値 2:届出内共通
A35: =A34+1 -> 19 | B35: 退職金支給明細書・支給前公開日数 | C35: retirement_pay_slip_before_pay_open_days | D35: smallint
A36: =A35+1 -> 20 | B36: 退職金支給明細書・公開除外日 | C36: retirement_pay_slip_excluded_days | D36: json | N36: {["name":"月","value":0/1], ["name":"火","value":0/1], ["name":"水","value":0/1], ["name":"木","value":0/1], ["name":"金","value":0/1], ["name":"土","value":0/1], ["name":"日","value":0/1], ["name":"祝","value":0/1]}
A37: =A36+1 -> 21 | B37: 退職金計算書・設定区分 | C37: retirement_calc_statement_use_type | D37: tinyint | N37: 1:既定値 2:届出内共通
A38: =A37+1 -> 22 | B38: 退職金計算書・支給前公開日数 | C38: retirement_calc_statement_before_pay_open_days | D38: smallint
A39: =A38+1 -> 23 | B39: 退職金計算書・公開除外日 | C39: retirement_calc_statement_excluded_days | D39: json | N39: {["name":"月","value":0/1], ["name":"火","value":0/1], ["name":"水","value":0/1], ["name":"木","value":0/1], ["name":"金","value":0/1], ["name":"土","value":0/1], ["name":"日","value":0/1], ["name":"祝","value":0/1]}
A40: =A39+1 -> 24 | B40: 退職給所得源泉徴収書・設定区分 | C40: retirement_withholding Statement_use_type | D40: tinyint | N40: 1:既定値 2:届出内共通
A41: =A40+1 -> 25 | B41: 退職給所得源泉徴収書・支給前公開日数 | C41: retirement_withholding Statement_before_pay_open_days | D41: smallint
A42: =A41+1 -> 26 | B42: 退職給所得源泉徴収書・公開除外日 | C42: retirement_withholding Statement_excluded_days | D42: json | N42: {["name":"月","value":0/1], ["name":"火","value":0/1], ["name":"水","value":0/1], ["name":"木","value":0/1], ["name":"金","value":0/1], ["name":"土","value":0/1], ["name":"日","value":0/1], ["name":"祝","value":0/1]}
A43: =A33+1 -> 18 | B43: 休職者計算区分 | C43: leave_employee_calc type | D43: tinyint | N43: 1:計算する 2:計算しない
...

Sheet テーブル一覧
B1: テーブル一覧
B2: システム | C2: 論理テーブル名 | D2: 物理テーブル名 | I2: 論理名 | J2: 備考
D3: 用途 | E3: Sociaプロダクト | F3: データ種類 | G3: テーブル名 | H3: フルテーブル名
B4: 給与システム | C4: =HYPERLINK("#'"&I4&"'!A1",I4) -> v社員二以上事業所勤務情報 | G4: v_syain_multi_office_kinmu_info | H4: v_syain_multi_office_kinmu_info | I4: v社員二以上事業所勤務情報
B5: 給与システム | C5: =HYPERLINK("#'"&I5&"'!A1",I5) -> v社員介護保険 | G5: v_syain_care_insurance | H5: v_syain_care_insurance | I5: v社員介護保険
B6: 給与システム | C6: =HYPERLINK("#'"&I6&"'!A1",I6) -> v社員住民税納付先住所 | G6: v_syain_family_resident_tax_address | H6: v_syain_family_resident_tax_address | I6: v社員住民税納付先住所
B7: 給与システム | C7: =HYPERLINK("#'"&I7&"'!A1",I7) -> v社員体系 | G7: v_syain_taikei | H7: v_syain_taikei | I7: v社員体系
B8: 給与システム | C8: =HYPERLINK("#'"&I8&"'!A1",I8) -> v社員保険資格取得 | G8: v_syain_insurance_qualification_get | H8: v_syain_insurance_qualification_get | I8: v社員保険資格取得
B9: 給与システム | C9: =HYPERLINK("#'"&I9&"'!A1",I9) -> v社員保険資格喪失 | G9: v_syain_insurance_qualification_loss | H9: v_syain_insurance_qualification_loss | I9: v社員保険資格喪失
B10: 給与システム | C10: =HYPERLINK("#'"&I10&"'!A1",I10) -> v社員健康保険 | G10: v_syain_health_insurance | H10: v_syain_health_insurance | I10: v社員健康保険
B11: 給与システム | C11: =HYPERLINK("#'"&I11&"'!A1",I11) -> v社員厚生年金 | G11: v_syain_kosei_pension | H11: v_syain_kosei_pension | I11: v社員厚生年金
B12: 給与システム | C12: =HYPERLINK("#'"&I12&"'!A1",I12) -> v社員基本 | G12: v_syain_basic | H12: v_syain_basic | I12: v社員基本
B13: 給与システム | C13: =HYPERLINK("#'"&I13&"'!A1",I13) -> v社員家族 | G13: v_syain_family | H13: v_syain_family | I13: v社員家族
B14: 給与システム | C14: =HYPERLINK("#'"&I14&"'!A1",I14) -> v社員届出異動履歴 | G14: v_syain_submission_transfer_history | H14: v_syain_submission_transfer_history | I14: v社員届出異動履歴
B15: 給与システム | C15: =HYPERLINK("#'"&I15&"'!A1",I15) -> v社員社会保険関連個人情報 | G15: v_syain_syaho_personal_info | H15: v_syain_syaho_personal_info | I15: v社員社会保険関連個人情報
... B138: 給与システム | C138: =HYPERLINK("#'"&I138&"'!A1",I138) -> 項目 | G138: item | H138: item | I138: 項目

Sheet v社員二以上事業所勤務情報
A1: テーブル情報
B2: システム名 | C2: SOCIA | E2: 作成者 | I2: ITSP | M2: テーブル一覧へ
B3: サブシステム名 | C3: 給与 | E3: 作成日 | I3: 2025-11-28
B4: スキーマ名 | E4: RDBMS | I4: MySQL
B5: 論理テーブル名 | C5: v社員二以上事業所勤務情報 | E5: ENGINE | I5: InnoDB
B6: 物理テーブル名 | C6: v_syain_multi_office_kinmu_info | E6: CHARSET | I6: utf8mb4
B7: 備考
B8: 論理テーブル
A12: カラム情報 | L12: 外部キー情報
A13: No | B13: 論理名 | C13: 物理名 | D13: データ型 | E13: Size | F13: Not Null | G13: PK | H13: UK | I13: デフォルト | J13: 備考 | L13: 親テーブル | M13: 参照カラム
A14: 1 | B14: 社員連番 | C14: syainseq | D14: bigint | F14: not null | G14: 〇
A15: 2 | B15: 他社報酬合計 | C15: other_kaisya_reward_total | D15: bigint
A16: 3 | B16: 標準報酬月額 | C16: standard_reward_month_amount | D16: bigint
A17: 4 | B17: 改定年 | C17: revision_year | D17: smallint
A18: 5 | B18: 改定月 | C18: revision_month | D18: smallint
A19: 6 | B19: 作成者 | C19: created_by | D19: bigint | F19: not null
A20: 7 | B20: 作成日時 | C20: created_at | D20: datetime | E20: 6 | F20: not null
A21: 8 | B21: 更新者 | C21: updated_by | D21: bigint | F21: not null
A22: 9 | B22: 更新日時 | C22: updated_at | D22: datetime | E22: 6 | F22: not null

Sheet v社員介護保険
A1: テーブル情報
B2: システム名 | C2: SOCIA | E2: 作成者 | I2: ITSP | M2: テーブル一覧へ
B3: サブシステム名 | C3: 給与 | E3: 作成日 | I3: 2025-11-28
B4: スキーマ名 | E4: RDBMS | I4: MySQL
B5: 論理テーブル名 | C5: v社員介護保険 | E5: ENGINE | I5: InnoDB
B6: 物理テーブル名 | C6: v_syain_care_insurance | E6: CHARSET | I6: utf8mb4
B7: 備考
B8: 論理テーブル
A12: カラム情報 | L12: 外部キー情報
A13: No | B13: 論理名 | C13: 物理名 | D13: データ型 | E13: Size | F13: Not Null | G13: PK | H13: UK | I13: デフォルト | J13: 備考 | L13: 親テーブル | M13: 参照カラム
A14: 1 | B14: 社員連番 | C14: syainseq | D14: bigint | F14: not null | G14: 〇
A15: 2 | B15: 介護保険区分 | C15: care_insurance_type | D15: tinyint
A16: 3 | B16: 作成者 | C16: created_by | D16: bigint | F16: not null
A17: 4 | B17: 作成日時 | C17: created_at | D17: datetime | E17: 6 | F17: not null
A18: 5 | B18: 更新者 | C18: updated_by | D18: bigint | F18: not null
A19: 6 | B19: 更新日時 | C19: updated_at | D19: datetime | E19: 6 | F19: not null

Sheet v社員住民税納付先住所
A1: テーブル情報
B2: システム名 | C2: SOCIA | E2: 作成者 | I2: ITSP | M2: テーブル一覧へ
B3: サブシステム名 | C3: 給与 | E3: 作成日 | I3: 2025-11-28
B4: スキーマ名 | E4: RDBMS | I4: MySQL
B5: 論理テーブル名 | C5: v社員住民税納付先住所 | E5: ENGINE | I5: InnoDB
B6: 物理テーブル名 | C6: v_syain_family_resident_tax_address | E6: CHARSET | I6: utf8mb4
B7: 備考
B8: 論理テーブル
A12: カラム情報 | L12: 外部キー情報
A13: No | B13: 論理名 | C13: 物理名 | D13: データ型 | E13: Size | F13: Not Null | G13: PK | H13: UK | I13: デフォルト | J13: 備考 | L13: 親テーブル | M13: 参照カラム
A14: 1 | B14: 社員連番 | C14: syainseq | D14: bigint | F14: not null | G14: 〇
A15: 2 | B15: 地方自治体コード | C15: local_municipality_code | D15: varchar | E15: 20
A16: 3 | B16: 個人番号 | C16: my_number | D16: varchar | E16: 10
A17: 4 | B17: 作成者 | C17: created_by | D17: bigint | F17: not null
A18: 5 | B18: 作成日時 | C18: created_at | D18: datetime | E18: 6 | F18: not null
A19: 6 | B19: 更新者 | C19: updated_by | D19: bigint | F19: not null
A20: 7 | B20: 更新日時 | C20: updated_at | D20: datetime | E20: 6 | F20: not null

Sheet v社員体系
A1: テーブル情報
B2: システム名 | C2: SOCIA | E2: 作成者 | I2: ITSP | M2: テーブル一覧へ
B3: サブシステム名 | C3: 給与 | E3: 作成日 | I3: 2025-11-28
B4: スキーマ名 | E4: RDBMS | I4: MySQL
B5: 論理テーブル名 | C5: v社員体系 | E5: ENGINE | I5: InnoDB
B6: 物理テーブル名 | C6: v_syain_taikei | E6: CHARSET | I6: utf8mb4
B7: 備考
B8: 論理テーブル
A12: カラム情報 | L12: 外部キー情報
A13: No | B13: 論理名 | C13: 物理名 | D13: データ型 | E13: Size | F13: Not Null | G13: PK | H13: UK | I13: デフォルト | J13: 備考 | L13: 親テーブル | M13: 参照カラム
A14: 1 | B14: 社員連番 | C14: syainseq | D14: bigint | F14: not null | G14: 〇
A15: 2 | B15: 支給区分 | C15: payment_type | D15: tinyint | F15: not null | G15: 〇
A16: 3 | B16: 体系コード | C16: taikei_code | D16: varchar | E16: 20
A17: 4 | B17: 作成者 | C17: created_by | D17: bigint | F17: not null
A18: 5 | B18: 作成日時 | C18: created_at | D18: datetime | E18: 6 | F18: not null
A19: 6 | B19: 更新者 | C19: updated_by | D19: bigint | F19: not null
A20: 7 | B20: 更新日時 | C20: updated_at | D20: datetime | E20: 6 | F20: not null

Sheet v社員保険資格取得
A1: テーブル情報
B2: システム名 | C2: SOCIA | E2: 作成者 | I2: ITSP | M2: テーブル一覧へ
B3: サブシステム名 | C3: 給与 | E3: 作成日 | I3: 2025-11-28
B4: スキーマ名 | E4: RDBMS | I4: MySQL
B5: 論理テーブル名 | C5: v社員保険資格取得 | E5: ENGINE | I5: InnoDB
B6: 物理テーブル名 | C6: v_syain_insurance_qualification_get | E6: CHARSET | I6: utf8mb4
B7: 備考
B8: 論理テーブル
A12: カラム情報 | L12: 外部キー情報
A13: No | B13: 論理名 | C13: 物理名 | D13: データ型 | E13: Size | F13: Not Null | G13: PK | H13: UK | I13: デフォルト | J13: 備考 | L13: 親テーブル | M13: 参照カラム
A14: 1 | B14: 社員連番 | C14: syainseq | D14: bigint | F14: not null | G14: 〇
A15: 2 | B15: 資格取得年月日 | C15: qualification_get_date | D15: date
A16: 3 | B16: 取得対象 | C16: get_target | D16: tinyint
A17: 4 | B17: 取得区分 | C17: get_type | D17: tinyint
A18: 5 | B18: 金銭 | C18: cash | D18: bigint
A19: 6 | B19: 現物 | C19: in_kind | D19: bigint
A20: 7 | B20: 合計 | C20: total | D20: bigint
A21: 8 | B21: 老齢年金給付区分 | C21: elderly_pension_grant_type | D21: tinyint
A22: 9 | B22: 被扶養者届区分 | C22: dependent_submission_type | D22: tinyint
A23: 10 | B23: 備考 | C23: note | D23: text
A24: 11 | B24: 資格確認書発行要否 | C24: qualification_confirm_report_issue_flag | D24: tinyint
A25: 12 | B25: 作成者 | C25: created_by | D25: bigint | F25: not null
A26: 13 | B26: 作成日時 | C26: created_at | D26: datetime | E26: 6 | F26: not null
A27: 14 | B27: 更新者 | C27: updated_by | D27: bigint | F27: not null
A28: 15 | B28: 更新日時 | C28: updated_at | D28: datetime | E28: 6 | F28: not null

Sheet v社員保険資格喪失
A1: テーブル情報
B2: システム名 | C2: SOCIA | E2: 作成者 | I2: ITSP | M2: テーブル一覧へ
B3: サブシステム名 | C3: 給与 | E3: 作成日 | I3: 2025-11-28
B4: スキーマ名 | E4: RDBMS | I4: MySQL
B5: 論理テーブル名 | C5: v社員保険資格喪失 | E5: ENGINE | I5: InnoDB
B6: 物理テーブル名 | C6: v_syain_insurance_qualification_loss | E6: CHARSET | I6: utf8mb4
B7: 備考
B8: 論理テーブル
A12: カラム情報 | L12: 外部キー情報
A13: No | B13: 論理名 | C13: 物理名 | D13: データ型 | E13: Size | F13: Not Null | G13: PK | H13: UK | I13: デフォルト | J13: 備考 | L13: 親テーブル | M13: 参照カラム
A14: 1 | B14: 社員連番 | C14: syainseq | D14: bigint | F14: not null | G14: 〇
A15: 2 | B15: 資格喪失年月日 | C15: qualification_loss_date | D15: date
A16: 3 | B16: 資格喪失対象 | C16: qualification_loss_target | D16: tinyint
A17: 4 | B17: 喪失区分 | C17: loss_type | D17: tinyint
A18: 5 | B18: 被保険者証回収区分 | C18: insured_person_card_return_type | D18: tinyint
A19: 6 | B19: ５５条届出区分 | C19: article55_submission_type | D19: tinyint
A20: 7 | B20: 備考 | C20: note | D20: text
A21: 8 | B21: 添付枚数 | C21: attachments_count | D21: bigint
A22: 9 | B22: 返不能枚数 | C22: return_non_count | D22: bigint
A23: 10 | B23: 作成者 | C23: created_by | D23: bigint | F23: not null
A24: 11 | B24: 作成日時 | C24: created_at | D24: datetime | E24: 6 | F24: not null
A25: 12 | B25: 更新者 | C25: updated_by | D25: bigint | F25: not null
A26: 13 | B26: 更新日時 | C26: updated_at | D26: datetime | E26: 6 | F26: not null

Sheet v社員健康保険
A1: テーブル情報
B2: システム名 | C2: SOCIA | E2: 作成者 | I2: ITSP | M2: テーブル一覧へ
B3: サブシステム名 | C3: 給与 | E3: 作成日 | I3: 2025-11-28
B4: スキーマ名 | E4: RDBMS | I4: MySQL
B5: 論理テーブル名 | C5: v社員健康保険 | E5: ENGINE | I5: InnoDB
B6: 物理テーブル名 | C6: v_syain_health_insurance | E6: CHARSET | I6: utf8mb4
B7: 備考
B8: 論理テーブル
A12: カラム情報 | L12: 外部キー情報
A13: No | B13: 論理名 | C13: 物理名 | D13: データ型 | E13: Size | F13: Not Null | G13: PK | H13: UK | I13: デフォルト | J13: 備考 | L13: 親テーブル | M13: 参照カラム
A14: 1 | B14: 社員連番 | C14: syainseq | D14: bigint | F14: not null | G14: 〇
A15: 2 | B15: 標準報酬月額 | C15: standard_reward_month_amount | D15: bigint
A16: 3 | B16: 報酬 | C16: reward | D16: bigint
A17: 4 | B17: 改定年 | C17: revision_year | D17: smallint
A18: 5 | B18: 改定月 | C18: revision_month | D18: smallint
A19: 6 | B19: 作成者 | C19: created_by | D19: bigint | F19: not null
A20: 7 | B20: 作成日時 | C20: created_at | D20: datetime | E20: 6 | F20: not null
A21: 8 | B21: 更新者 | C21: updated_by | D21: bigint | F21: not null
A22: 9 | B22: 更新日時 | C22: updated_at | D22: datetime | E22: 6 | F22: not null

Sheet v社員厚生年金
A1: テーブル情報
B2: システム名 | C2: SOCIA | E2: 作成者 | I2: ITSP | M2: テーブル一覧へ
B3: サブシステム名 | C3: 給与 | E3: 作成日 | I3: 2025-11-28
B4: スキーマ名 | E4: RDBMS | I4: MySQL
B5: 論理テーブル名 | C5: v社員厚生年金 | E5: ENGINE | I5: InnoDB
B6: 物理テーブル名 | C6: v_syain_kosei_pension | E6: CHARSET | I6: utf8mb4
B7: 備考
B8: 論理テーブル
A12: カラム情報 | L12: 外部キー情報
A13: No | B13: 論理名 | C13: 物理名 | D13: データ型 | E13: Size | F13: Not Null | G13: PK | H13: UK | I13: デフォルト | J13: 備考 | L13: 親テーブル | M13: 参照カラム
A14: 1 | B14: 社員連番 | C14: syainseq | D14: bigint | F14: not null | G14: 〇
A15: 2 | B15: 標準報酬月額 | C15: standard_reward_month_amount | D15: bigint
A16: 3 | B16: 報酬 | C16: reward | D16: bigint
A17: 4 | B17: 改定年 | C17: revision_year | D17: smallint
A18: 5 | B18: 改定月 | C18: revision_month | D18: smallint
A19: 6 | B19: 作成者 | C19: created_by | D19: bigint | F19: not null
A20: 7 | B20: 作成日時 | C20: created_at | D20: datetime | E20: 6 | F20: not null
A21: 8 | B21: 更新者 | C21: updated_by | D21: bigint | F21: not null
A22: 9 | B22: 更新日時 | C22: updated_at | D22: datetime | E22: 6 | F22: not null

Sheet v社員基本
A1: テーブル情報
B2: システム名 | C2: SOCIA | E2: 作成者 | I2: ITSP | M2: テーブル一覧へ
B3: サブシステム名 | C3: 給与 | E3: 作成日 | I3: 2025-11-28
B4: スキーマ名 | E4: RDBMS | I4: MySQL
B5: 論理テーブル名 | C5: v社員基本 | E5: ENGINE | I5: InnoDB
B6: 物理テーブル名 | C6: v_syain_basic | E6: CHARSET | I6: utf8mb4
B7: 備考
B8: 論理テーブル
A12: カラム情報 | L12: 外部キー情報
A13: No | B13: 論理名 | C13: 物理名 | D13: データ型 | E13: Size | F13: Not Null | G13: PK | H13: UK | I13: デフォルト | J13: 備考 | L13: 親テーブル | M13: 参照カラム
A14: 1 | B14: 社員連番 | C14: syainseq | D14: bigint | F14: not null | G14: 〇
A15: 2 | B15: 会社コード | C15: kaisyacd | D15: varchar | E15: 20
A16: 3 | B16: 社員コード | C16: syaincd | D16: varchar | E16: 20
A17: 4 | B17: 氏名 | C17: name | D17: varchar | E17: 255
A18: 5 | B18: フリガナ | C18: furigana | D18: varchar | E18: 20
A19: 6 | B19: 生年月日 | C19: birth_date | D19: date
A20: 7 | B20: 性別区分 | C20: sex_type | D20: tinyint
A21: 8 | B21: 入社年月日 | C21: entrycompany_date | D21: date
A22: 9 | B22: 休・退職区分 | C22: leave_retirement_type | D22: tinyint
A23: 10 | B23: 地方自治体コード | C23: local_municipality_code | D23: varchar | E23: 20
A24: 11 | B24: 住所 | C24: address | D24: varchar | E24: 100
A25: 12 | B25: 住所カナ | C25: address_kana | D25: varchar | E25: 100
A26: 13 | B26: 退職年月日 | C26: retirement_date | D26: date
A27: 14 | B27: 事業所コード | C27: office_code | D27: varchar | E27: 20
A28: 15 | B28: 所属コード | C28: belong_code | D28: varchar | E28: 20
A29: 16 | B29: 部門コード | C29: department_code | D29: varchar | E29: 20
A30: 17 | B30: 郵便番号 | C30: postal_code | D30: varchar | E30: 10
A31: 18 | B31: みなし入社年月日 | C31: deem_entrycompany_date | D31: date
A32: 19 | B32: 役員区分 | C32: officer_type | D32: tinyint
A33: 20 | B33: 弁護士区分 | C33: lawyer_type | D33: tinyint
A34: 21 | B34: 給与区分 | C34: kyuyo_type | D34: tinyint
A35: 22 | B35: データ連番 | C35: dataseq | D35: int
A36: 23 | B36: 住民税区分 | C36: resident_tax_type | D36: tinyint
A37: 24 | B37: 届出コード | C37: submission_code | D37: varchar | E37: 20
A38: 25 | B38: パート区分 | C38: part_type | D38: tinyint
A39: 26 | B39: 健康保険番号 | C39: health_insurance_number | D39: varchar | E39: 20
A40: 27 | B40: 基礎年金番号 | C40: basic_pension_number | D40: varchar | E40: 20
A41: 28 | B41: 年金整理番号 | C41: pension_arrangement_number | D41: varchar | E41: 20
A42: 29 | B42: 作成者 | C42: created_by | D42: bigint | F42: not null
A43: 30 | B43: 作成日時 | C43: created_at | D43: datetime | E43: 6 | F43: not null
...

Sheet v社員家族
A1: テーブル情報
B2: システム名 | C2: SOCIA | E2: 作成者 | I2: ITSP | M2: テーブル一覧へ
B3: サブシステム名 | C3: 給与 | E3: 作成日 | I3: 2025-11-28
B4: スキーマ名 | E4: RDBMS | I4: MySQL
B5: 論理テーブル名 | C5: v社員家族 | E5: ENGINE | I5: InnoDB
B6: 物理テーブル名 | C6: v_syain_family | E6: CHARSET | I6: utf8mb4
B7: 備考
B8: 論理テーブル
A12: カラム情報 | L12: 外部キー情報
A13: No | B13: 論理名 | C13: 物理名 | D13: データ型 | E13: Size | F13: Not Null | G13: PK | H13: UK | I13: デフォルト | J13: 備考 | L13: 親テーブル | M13: 参照カラム
A14: 1 | B14: 社員連番 | C14: syainseq | D14: bigint | F14: not null | G14: 〇
A15: 2 | B15: データ連番 | C15: dataseq | D15: int | F15: not null | G15: 〇
A16: 3 | B16: 表示順序 | C16: dsp_order | D16: bigint
A17: 4 | B17: 氏名 | C17: name | D17: varchar | E17: 255
A18: 5 | B18: フリガナ | C18: furigana | D18: varchar | E18: 20
A19: 6 | B19: 性別区分 | C19: sex_type | D19: tinyint
A20: 7 | B20: 郵便番号 | C20: postal_code | D20: varchar | E20: 10
A21: 8 | B21: 住所 | C21: address | D21: varchar | E21: 100
A22: 9 | B22: 生年月日 | C22: birth_date | D22: date
A23: 10 | B23: 続柄コード | C23: relation_code | D23: varchar | E23: 20
A24: 11 | B24: 職業コード | C24: occupation_code | D24: varchar | E24: 20
A25: 12 | B25: 職業名称 | C25: occupation_name | D25: varchar | E25: 255
A26: 13 | B26: 同居区分 | C26: cohabitation_type | D26: tinyint
A27: 14 | B27: 扶養区分 | C27: dependent_type | D27: tinyint
A28: 15 | B28: 障害者区分 | C28: disability_type | D28: tinyint
A29: 16 | B29: 同一生計区分 | C29: same_household_type | D29: tinyint
A30: 17 | B30: 非居住者区分 | C30: nonresident_type | D30: tinyint
A31: 18 | B31: 非居住理由区分 | C31: nonresident_reason_type | D31: tinyint
A32: 19 | B32: 寡婦区分 | C32: widow_type | D32: tinyint
A33: 20 | B33: 配偶者区分 | C33: spouse_type | D33: tinyint
A34: 21 | B34: 市区町村名称 | C34: municipalities_name | D34: varchar | E34: 255
A35: 22 | B35: 事業所名称 | C35: office_name | D35: varchar | E35: 255
A36: 23 | B36: 所属名称 | C36: belong_name | D36: varchar | E36: 255
A37: 24 | B37: 事業所略称 | C37: office_shortname | D37: varchar | E37: 255
A38: 25 | B38: 所属略称 | C38: belong_shortname | D38: varchar | E38: 255
A39: 26 | B39: 作成者 | C39: created_by | D39: bigint | F39: not null
A40: 27 | B40: 作成日時 | C40: created_at | D40: datetime | E40: 6 | F40: not null
A41: 28 | B41: 更新者 | C41: updated_by | D41: bigint | F41: not null
A42: 29 | B42: 更新日時 | C42: updated_at | D42: datetime | E42: 6 | F42: not null

Sheet v社員届出異動履歴
A1: テーブル情報
B2: システム名 | C2: SOCIA | E2: 作成者 | I2: ITSP | M2: テーブル一覧へ
B3: サブシステム名 | C3: 給与 | E3: 作成日 | I3: 2025-11-28
B4: スキーマ名 | E4: RDBMS | I4: MySQL
B5: 論理テーブル名 | C5: v社員届出異動履歴 | E5: ENGINE | I5: InnoDB
B6: 物理テーブル名 | C6: v_syain_submission_transfer_history | E6: CHARSET | I6: utf8mb4
B7: 備考
B8: 論理テーブル。履歴テーブル
A12: カラム情報 | L12: 外部キー情報
A13: No | B13: 論理名 | C13: 物理名 | D13: データ型 | E13: Size | F13: Not Null | G13: PK | H13: UK | I13: デフォルト | J13: 備考 | L13: 親テーブル | M13: 参照カラム
A14: 1 | B14: 社員連番 | C14: syainseq | D14: bigint | F14: not null | G14: 〇
A15: 2 | B15: 有効開始年月日 | C15: fromymd | D15: date | F15: not null | G15: 〇
A16: 3 | B16: 有効終了年月日 | C16: toymd | D16: date
A17: 4 | B17: 届出コード | C17: submission_code | D17: varchar | E17: 20
A18: 5 | B18: 作成者 | C18: created_by | D18: bigint | F18: not null
A19: 6 | B19: 作成日時 | C19: created_at | D19: datetime | E19: 6 | F19: not null
A20: 7 | B20: 更新者 | C20: updated_by | D20: bigint | F20: not null
A21: 8 | B21: 更新日時 | C21: updated_at | D21: datetime | E21: 6 | F21: not null

Sheet v社員社会保険関連個人情報
A1: テーブル情報
B2: システム名 | C2: SOCIA | E2: 作成者 | I2: ITSP | M2: テーブル一覧へ
B3: サブシステム名 | C3: 給与 | E3: 作成日 | I3: 2025-11-28
B4: スキーマ名 | E4: RDBMS | I4: MySQL
B5: 論理テーブル名 | C5: v社員社会保険関連個人情報 | E5: ENGINE | I5: InnoDB
B6: 物理テーブル名 | C6: v_syain_syaho_personal_info | E6: CHARSET | I6: utf8mb4
B7: 備考
B8: 論理テーブル
A12: カラム情報 | L12: 外部キー情報
A13: No | B13: 論理名 | C13: 物理名 | D13: データ型 | E13: Size | F13: Not Null | G13: PK | H13: UK | I13: デフォルト | J13: 備考 | L13: 親テーブル | M13: 参照カラム
A14: 1 | B14: 社員連番 | C14: syainseq | D14: bigint | F14: not null | G14: 〇
A15: 2 | B15: データ区分 | C15: data_type | D15: bigint
A16: 3 | B16: 種別区分 | C16: class_type | D16: tinyint
A17: 4 | B17: 種別コード | C17: class_code | D17: varchar | E17: 20
A18: 5 | B18: 理由 | C18: reason | D18: varchar | E18: 255
A19: 6 | B19: 作成者 | C19: created_by | D19: bigint | F19: not null
A20: 7 | B20: 作成日時 | C20: created_at | D20: datetime | E20: 6 | F20: not null
A21: 8 | B21: 更新者 | C21: updated_by | D21: bigint | F21: not null
A22: 9 | B22: 更新日時 | C22: updated_at | D22: datetime | E22: 6 | F22: not null

Sheet v社員税法
A1: テーブル情報
B2: システム名 | C2: SOCIA | E2: 作成者 | I2: ITSP | M2: テーブル一覧へ
B3: サブシステム名 | C3: 給与 | E3: 作成日 | I3: 2025-11-28
B4: スキーマ名 | E4: RDBMS | I4: MySQL
B5: 論理テーブル名 | C5: v社員税法 | E5: ENGINE | I5: InnoDB
B6: 物理テーブル名 | C6: v_syain_tax_law | E6: CHARSET | I6: utf8mb4
B7: 備考
B8: 論理テーブル
A12: カラム情報 | L12: 外部キー情報
A13: No | B13: 論理名 | C13: 物理名 | D13: データ型 | E13: Size | F13: Not Null | G13: PK | H13: UK | I13: デフォルト | J13: 備考 | L13: 親テーブル | M13: 参照カラム
A14: 1 | B14: 社員連番 | C14: syainseq | D14: bigint | F14: not null | G14: 〇
A15: 2 | B15: 課税区分 | C15: tax_type | D15: tinyint
A16: 3 | B16: 居住者区分 | C16: resident_type | D16: tinyint
A17: 4 | B17: 障害者区分 | C17: disability_type | D17: tinyint
A18: 5 | B18: 寡婦区分 | C18: widow_type | D18: tinyint
A19: 6 | B19: 学生区分 | C19: student_type | D19: tinyint
A20: 7 | B20: 未成年者区分 | C20: minor_type | D20: tinyint
A21: 8 | B21: 死亡退職区分 | C21: death_retirement_type | D21: tinyint
A22: 9 | B22: 災害者区分 | C22: disaster_type | D22: tinyint
A23: 10 | B23: 外国人区分 | C23: foreigner_type | D23: tinyint
A24: 11 | B24: 配偶者区分 | C24: spouse_type | D24: tinyint
A25: 12 | B25: 親族扶養区分 | C25: relative_dependent_type | D25: tinyint
A26: 13 | B26: 親族一般扶養 | C26: relative_general_dependent | D26: tinyint
... A45: 32 | B45: 厚生年金基金区分 | C45: kosei_pension_fund_type | D45: tinyint
A46: 33 | B46: 作成者 | C46: created_by | D46: bigint | F46: not null
A47: 34 | B47: 作成日時 | C47: created_at | D47: datetime | E47: 6 | F47: not null
A48: 35 | B48: 更新者 | C48: updated_by | D48: bigint | F48: not null
A49: 36 | B49: 更新日時 | C49: updated_at | D49: datetime | E49: 6 | F49: not null

Sheet v社員締日
A1: テーブル情報
B2: システム名 | C2: SOCIA | E2: 作成者 | I2: ITSP | M2: テーブル一覧へ
B3: サブシステム名 | C3: 給与 | E3: 作成日 | I3: 2025-11-28
B4: スキーマ名 | E4: RDBMS | I4: MySQL
B5: 論理テーブル名 | C5: v社員締日 | E5: ENGINE | I5: InnoDB
B6: 物理テーブル名 | C6: v_syain_shime_day | E6: CHARSET | I6: utf8mb4
B7: 備考
B8: 論理テーブル
A12: カラム情報 | L12: 外部キー情報
A13: No | B13: 論理名 | C13: 物理名 | D13: データ型 | E13: Size | F13: Not Null | G13: PK | H13: UK | I13: デフォルト | J13: 備考 | L13: 親テーブル | M13: 参照カラム
A14: 1 | B14: 社員連番 | C14: syainseq | D14: bigint | F14: not null | G14: 〇
A15: 2 | B15: 締日 | C15: shime_day | D15: tinyint | F15: not null | G15: 〇
A16: 3 | B16: 支給月区分 | C16: payment_month_type | D16: tinyint | F16: not null | G16: 〇
A17: 4 | B17: 支給日 | C17: payment_day | D17: tinyint | F17: not null | G17: 〇
A18: 5 | B18: 作成者 | C18: created_by | D18: bigint | F18: not null
A19: 6 | B19: 作成日時 | C19: created_at | D19: datetime | E19: 6 | F19: not null
A20: 7 | B20: 更新者 | C20: updated_by | D20: bigint | F20: not null
A21: 8 | B21: 更新日時 | C21: updated_at | D21: datetime | E21: 6 | F21: not null

Sheet v社員賞与時社保徴収先
A1: テーブル情報
B2: システム名 | C2: SOCIA | E2: 作成者 | I2: ITSP | M2: テーブル一覧へ
B3: サブシステム名 | C3: 給与 | E3: 作成日 | I3: 2025-11-28
B4: スキーマ名 | E4: RDBMS | I4: MySQL
B5: 論理テーブル名 | C5: v社員賞与時社保徴収先 | E5: ENGINE | I5: InnoDB
B6: 物理テーブル名 | C6: v_syain_syoyo_syaho_collateral | E6: CHARSET | I6: utf8mb4
B7: 備考
B8: 論理テーブル
A12: カラム情報 | L12: 外部キー情報
A13: No | B13: 論理名 | C13: 物理名 | D13: データ型 | E13: Size | F13: Not Null | G13: PK | H13: UK | I13: デフォルト | J13: 備考 | L13: 親テーブル | M13: 参照カラム
A14: 1 | B14: 社員連番 | C14: syainseq | D14: bigint | F14: not null | G14: 〇
A15: 2 | B15: 徴収先区分 | C15: collateral_type | D15: tinyint
A16: 3 | B16: 作成者 | C16: created_by | D16: bigint | F16: not null
A17: 4 | B17: 作成日時 | C17: created_at | D17: datetime | E17: 6 | F17: not null
A18: 5 | B18: 更新者 | C18: updated_by | D18: bigint | F18: not null
A19: 6 | B19: 更新日時 | C19: updated_at | D19: datetime | E19: 6 | F19: not null

Sheet v社員銀行
A1: テーブル情報
B2: システム名 | C2: SOCIA | E2: 作成者 | I2: ITSP | M2: テーブル一覧へ
B3: サブシステム名 | C3: 給与 | E3: 作成日 | I3: 2025-11-28
B4: スキーマ名 | E4: RDBMS | I4: MySQL
B5: 論理テーブル名 | C5: v社員銀行 | E5: ENGINE | I5: InnoDB
B6: 物理テーブル名 | C6: v_syain_bank | E6: CHARSET | I6: utf8mb4
B7: 備考
B8: 論理テーブル
A12: カラム情報 | L12: 外部キー情報
A13: No | B13: 論理名 | C13: 物理名 | D13: データ型 | E13: Size | F13: Not Null | G13: PK | H13: UK | I13: デフォルト | J13: 備考 | L13: 親テーブル | M13: 参照カラム
A14: 1 | B14: 社員連番 | C14: syainseq | D14: bigint | F14: not null | G14: 〇
A15: 2 | B15: 支給区分 | C15: payment_type | D15: tinyint | F15: not null | G15: 〇
A16: 3 | B16: 処理順序 | C16: process_order | D16: bigint | F16: not null | G16: 〇
A17: 4 | B17: 振込元銀行連番 | C17: remitter_bank_seq | D17: bigint
A18: 5 | B18: 銀行コード | C18: bank_code | D18: varchar | E18: 20
A19: 6 | B19: 支店コード | C19: branch_code | D19: varchar | E19: 20
A20: 7 | B20: 口座種別区分 | C20: account_class_type | D20: tinyint
A21: 8 | B21: 口座番号 | C21: account_number | D21: bigint
A22: 9 | B22: 別名義振込氏名 | C22: different_name_remitter_name | D22: varchar | E22: 255
A23: 10 | B23: 別名義振込カナ | C23: different_name_remitter_kana | D23: varchar | E23: 255
A24: 11 | B24: 振込区分 | C24: transfer_type | D24: tinyint
A25: 12 | B25: 設定値 | C25: setvalue | D25: varchar | E25: 255
A26: 13 | B26: 項目コード | C26: item_code | D26: varchar | E26: 20
A27: 14 | B27: 作成者 | C27: created_by | D27: bigint | F27: not null
A28: 15 | B28: 作成日時 | C28: created_at | D28: datetime | E28: 6 | F28: not null
A29: 16 | B29: 更新者 | C29: updated_by | D29: bigint | F29: not null
A30: 17 | B30: 更新日時 | C30: updated_at | D30: datetime | E30: 6 | F30: not null

Sheet 事業所整理記号情報
A1: テーブル情報
B2: システム名 | C2: SOCIA | E2: 作成者 | I2: ITSP | M2: テーブル一覧へ
B3: サブシステム名 | C3: 給与 | E3: 作成日 | I3: 2025-11-28
B4: スキーマ名 | E4: RDBMS | I4: MySQL
B5: 論理テーブル名 | C5: 事業所整理記号情報 | E5: ENGINE | I5: InnoDB
B6: 物理テーブル名 | C6: office_arrangement_mark_info | E6: CHARSET | I6: utf8mb4
B7: 備考
A12: カラム情報 | L12: 外部キー情報
A13: No | B13: 論理名 | C13: 物理名 | D13: データ型 | E13: Size | F13: Not Null | G13: PK | H13: UK | I13: デフォルト | J13: 備考 | L13: 親テーブル | M13: 参照カラム
A14: 1 | B14: 会社コード | C14: kaisyacd | D14: varchar | E14: 20 | F14: not null | G14: 〇
A15: 2 | B15: 届出コード | C15: submission_code | D15: varchar | E15: 20 | F15: not null | G15: 〇
A16: 3 | B16: 提出先区分 | C16: submission_type | D16: tinyint | F16: not null | G16: 〇
A17: 4 | B17: ＦＤ通番 | C17: fd_serialnumber | D17: smallint
A18: 5 | B18: 郡市区符号 | C18: city_code | D18: tinyint
A19: 6 | B19: 事業所記号 | C19: office_mark | D19: varchar | E19: 4
A20: 7 | B20: 都道府県コード | C20: state_code | D20: varchar | E20: 2
A21: 8 | B21: 作成者 | C21: created_by | D21: bigint | F21: not null
A22: 9 | B22: 作成日時 | C22: created_at | D22: datetime | E22: 6 | F22: not null
A23: 10 | B23: 更新者 | C23: updated_by | D23: bigint | F23: not null
A24: 11 | B24: 更新日時 | C24: updated_at | D24: datetime | E24: 6 | F24: not null

Sheet 介護保険会社情報
A1: テーブル情報
B2: システム名 | C2: SOCIA | E2: 作成者 | I2: ITSP | M2: テーブル一覧へ
B3: サブシステム名 | C3: 給与 | E3: 作成日 | I3: 2025-11-28
B4: スキーマ名 | E4: RDBMS | I4: MySQL
B5: 論理テーブル名 | C5: 介護保険会社情報 | E5: ENGINE | I5: InnoDB
B6: 物理テーブル名 | C6: care_insurance_kaisya_info | E6: CHARSET | I6: utf8mb4
B7: 備考
B8: #238673より、保険会社の事業部/届出 毎の必要がなくなる
A12: カラム情報 | L12: 外部キー情報
A13: No | B13: 論理名 | C13: 物理名 | D13: データ型 | E13: Size | F13: Not Null | G13: PK | H13: UK | I13: デフォルト | J13: 備考 | L13: 親テーブル | M13: 参照カラム
A14: 1 | B14: 会社コード | C14: kaisyacd | D14: varchar | E14: 20 | F14: not null | G14: 〇
A15: 2 | B15: 有効開始年月日 | C15: fromymd | D15: date | F15: not null | G15: 〇
A16: 3 | B16: 有効終了年月日 | C16: toymd | D16: date | F16: not null
A17: 4 | B17: 計算区分 | C17: equation_type | D17: tinyint | F17: not null | J17: 1:率(初期値)_x000D_ 2:表
A18: 5 | B18: 特定被保険者計算区分 | C18: specific_insured_person_equation_type | D18: tinyint | F18: not null | J18: 1:使用する(初期値)_x000D_ 2:使用しない
A19: 6 | B19: 介護被保険者 | C19: care_insured_person | D19: decimal | E19: 6,3 | F19: not null
A20: 7 | B20: 介護事業主 | C20: care_business_owner | D20: decimal | E20: 6,3 | F20: not null
A21: 8 | B21: 特別介護被保険者 | C21: special_care_insured_person | D21: decimal | E21: 6,3
A22: 9 | B22: 特別介護事業主 | C22: special_care_business_owner | D22: decimal | E22: 6,3
A23: 10 | B23: 作成者 | C23: created_by | D23: bigint | F23: not null
A24: 11 | B24: 作成日時 | C24: created_at | D24: datetime | E24: 6 | F24: not null
A25: 12 | B25: 更新者 | C25: updated_by | D25: bigint | F25: not null
A26: 13 | B26: 更新日時 | C26: updated_at | D26: datetime | E26: 6 | F26: not null

Sheet 介護保険料額
A1: テーブル情報
B2: システム名 | C2: SOCIA | E2: 作成者 | I2: ITSP | M2: テーブル一覧へ
B3: サブシステム名 | C3: 給与 | E3: 作成日 | I3: 2025-11-28
B4: スキーマ名 | E4: RDBMS | I4: MySQL
B5: 論理テーブル名 | C5: 介護保険料額 | E5: ENGINE | I5: InnoDB
B6: 物理テーブル名 | C6: care_insurance_amount | E6: CHARSET | I6: utf8mb4
B7: 備考
A12: カラム情報 | L12: 外部キー情報
A13: No | B13: 論理名 | C13: 物理名 | D13: データ型 | E13: Size | F13: Not Null | G13: PK | H13: UK | I13: デフォルト | J13: 備考 | L13: 親テーブル | M13: 参照カラム
A14: 1 | B14: 会社コード | C14: kaisyacd | D14: varchar | E14: 20 | F14: not null | G14: 〇
A15: 2 | B15: 届出コード | C15: submission_code | D15: varchar | E15: 20 | F15: not null | G15: 〇
A16: 3 | B16: 等級 | C16: grade | D16: smallint | F16: not null | G16: 〇
A17: 4 | B17: 有効開始年月日 | C17: fromymd | D17: date | F17: not null | G17: 〇
A18: 5 | B18: 有効終了年月日 | C18: toymd | D18: date | F18: not null
A19: 6 | B19: 標準報酬月額 | C19: standard_reward_month_amount | D19: bigint | F19: not null
A20: 7 | B20: 報酬月額 | C20: reward_monthly | D20: bigint
A21: 8 | B21: 被保険者 | C21: insured_person | D21: int | F21: not null
A22: 9 | B22: 事業主 | C22: business_owner | D22: int | F22: not null
A23: 10 | B23: 作成者 | C23: created_by | D23: bigint | F23: not null
A24: 11 | B24: 作成日時 | C24: created_at | D24: datetime | E24: 6 | F24: not null
A25: 12 | B25: 更新者 | C25: updated_by | D25: bigint | F25: not null
A26: 13 | B26: 更新日時 | C26: updated_at | D26: datetime | E26: 6 | F26: not null

Sheet 会社保険率
A1: テーブル情報
B2: システム名 | C2: SOCIA | E2: 作成者 | I2: ITSP | M2: テーブル一覧へ
B3: サブシステム名 | C3: 給与 | E3: 作成日 | I3: 2025-11-28
B4: スキーマ名 | E4: RDBMS | I4: MySQL
B5: 論理テーブル名 | C5: 会社保険率 | E5: ENGINE | I5: InnoDB
B6: 物理テーブル名 | C6: kaisya_insurance_rate | E6: CHARSET | I6: utf8mb4
B7: 備考
A12: カラム情報 | L12: 外部キー情報
A13: No | B13: 論理名 | C13: 物理名 | D13: データ型 | E13: Size | F13: Not Null | G13: PK | H13: UK | I13: デフォルト | J13: 備考 | L13: 親テーブル | M13: 参照カラム
A14: 1 | B14: 会社コード | C14: kaisyacd | D14: varchar | E14: 20 | F14: not null | G14: 〇
A15: 2 | B15: 届出コード | C15: submission_code | D15: varchar | E15: 20 | F15: not null | G15: 〇
A16: 3 | B16: 有効開始年月日 | C16: fromymd | D16: date | F16: not null | G16: 〇
A17: 4 | B17: 有効終了年月日 | C17: toymd | D17: date | F17: not null
A18: 5 | B18: 給与健康率被保険者(基本) | C18: kyuyo_health_rate_insured_person_basic | D18: decimal | E18: 6,3 | F18: not null
A19: 6 | B19: 給与健康率被保険者(特定) | C19: kyuyo_health_rate_insured_person_specific | D19: decimal | E19: 6,3 | F19: not null
A20: 7 | B20: 給与健康率事業主(基本) | C20: kyuyo_health_rate_business_owner_basic | D20: decimal | E20: 6,3 | F20: not null
A21: 8 | B21: 給与健康率事業主(特定) | C21: kyuyo_health_rate_business_owner_specific | D21: decimal | E21: 6,3 | F21: not null
A22: 9 | B22: 賞与健康率被保険者(基本) | C22: syoyo_health_rate_insured_person_basic | D22: decimal | E22: 6,3 | F22: not null
A23: 10 | B23: 賞与健康率被保険者(特定) | C23: syoyo_health_rate_insured_person_specific | D23: decimal | E23: 6,3 | F23: not null
A24: 11 | B24: 賞与健康率事業主(基本) | C24: syoyo_health_rate_business_owner_basic | D24: decimal | E24: 6,3 | F24: not null
A25: 12 | B25: 賞与健康率事業主(特定) | C25: syoyo_health_rate_business_owner_specific | D25: decimal | E25: 6,3 | F25: not null
A26: 13 | B26: 一般拠出金率 | C26: general_contribution_rate | D26: decimal | E26: 6,3
A27: 14 | B27: 作成者 | C27: created_by | D27: bigint | F27: not null
A28: 15 | B28: 作成日時 | C28: created_at | D28: datetime | E28: 6 | F28: not null
A29: 16 | B29: 更新者 | C29: updated_by | D29: bigint | F29: not null
A30: 17 | B30: 更新日時 | C30: updated_at | D30: datetime | E30: 6 | F30: not null

Sheet 会社地方自治体
A1: テーブル情報
B2: システム名 | C2: SOCIA | E2: 作成者 | I2: ITSP | M2: テーブル一覧へ
B3: サブシステム名 | C3: 給与 | E3: 作成日 | I3: 2025-11-28
B4: スキーマ名 | E4: RDBMS | I4: MySQL
B5: 論理テーブル名 | C5: 会社地方自治体 | E5: ENGINE | I5: InnoDB
B6: 物理テーブル名 | C6: kaisya_local_municipality | E6: CHARSET | I6: utf8mb4
B7: 備考
B8: 現行：QTISJITIとQTISKAISYAJITIの合体
A12: カラム情報 | L12: 外部キー情報
A13: No | B13: 論理名 | C13: 物理名 | D13: データ型 | E13: Size | F13: Not Null | G13: PK | H13: UK | I13: デフォルト | J13: 備考 | L13: 親テーブル | M13: 参照カラム
A14: 1 | B14: 会社コード | C14: kaisyacd | D14: varchar | E14: 20 | F14: not null | G14: 〇
A15: 2 | B15: 届出コード | C15: submission_code | D15: varchar | E15: 20 | F15: not null | G15: 〇
A16: 3 | B16: 市区町村コード | C16: municipalities_code | D16: varchar | E16: 20 | F16: not null | G16: 〇
A17: 4 | B17: 有効開始年月日 | C17: fromymd | D17: date | F17: not null | G17: 〇
A18: 5 | B18: 有効終了年月日 | C18: toymd | D18: date | F18: not null
A19: 6 | B19: 指定番号 | C19: specify_number | D19: varchar | E19: 12
A20: 7 | B20: 地方税納付先銀行コード | C20: local_tax_payee_bank_code | D20: varchar | E20: 20
A21: 8 | B21: 地方税納付先支店コード | C21: local_tax_payee_branch_code | D21: varchar | E21: 20
A22: 9 | B22: 依頼人番号 | C22: applicant_number | D22: bigint
A23: 10 | B23: 所在地（カナ） | C23: location_kana | D23: varchar | E23: 100
A24: 11 | B24: 作成者 | C24: created_by | D24: bigint | F24: not null
A25: 12 | B25: 作成日時 | C25: created_at | D25: datetime | E25: 6 | F25: not null
A26: 13 | B26: 更新者 | C26: updated_by | D26: bigint | F26: not null
A27: 14 | B27: 更新日時 | C27: updated_at | D27: datetime | E27: 6 | F27: not null

Sheet 会社端数処理情報
A1: テーブル情報
B2: システム名 | C2: SOCIA | E2: 作成者 | I2: ITSP | M2: テーブル一覧へ
B3: サブシステム名 | C3: 給与 | E3: 作成日 | I3: 2025-11-28
B4: スキーマ名 | E4: RDBMS | I4: MySQL
B5: 論理テーブル名 | C5: 会社端数処理情報 | E5: ENGINE | I5: InnoDB
B6: 物理テーブル名 | C6: kaisya_fraction_process_info | E6: CHARSET | I6: utf8mb4
B7: 備考
A12: カラム情報 | L12: 外部キー情報
A13: No | B13: 論理名 | C13: 物理名 | D13: データ型 | E13: Size | F13: Not Null | G13: PK | H13: UK | I13: デフォルト | J13: 備考 | L13: 親テーブル | M13: 参照カラム
A14: 1 | B14: 会社コード | C14: kaisyacd | D14: varchar | E14: 20 | F14: not null | G14: 〇
A15: 2 | B15: 届出コード | C15: submission_code | D15: varchar | E15: 20 | F15: not null | G15: 〇
A16: 3 | B16: 有効開始年月日 | C16: fromymd | D16: date | F16: not null | G16: 〇
A17: 4 | B17: 有効終了年月日 | C17: toymd | D17: date | F17: not null
A18: 5 | B18: 給与健康被保険者 | C18: kyuyo_health_insured_person | D18: tinyint | J18: コードマスタ.SQS0073
A19: 6 | B19: 給与健康事業主 | C19: kyuyo_health_business_owner | D19: tinyint | J19: コードマスタ.SQS0073
A20: 7 | B20: 給与介護被保険者 | C20: kyuyo_care_insured_person | D20: tinyint | J20: コードマスタ.SQS0073
A21: 8 | B21: 給与介護事業主 | C21: kyuyo_care_business_owner | D21: tinyint | J21: コードマスタ.SQS0073
A22: 9 | B22: 給与厚生年金被保険者 | C22: kyuyo_kosei_pension_insured_person | D22: tinyint | J22: コードマスタ.SQS0073
A23: 10 | B23: 給与厚生年金事業主 | C23: kyuyo_kosei_pension_business_owner | D23: tinyint | J23: コードマスタ.SQS0073
A24: 11 | B24: 給与厚生年金基金被保険者 | C24: kyuyo_kosei_pension_fund_insured_person | D24: tinyint | J24: コードマスタ.SQS0073
A25: 12 | B25: 給与厚生年金基金事業主 | C25: kyuyo_kosei_pension_fund_business_owner | D25: tinyint | J25: コードマスタ.SQS0073
A26: 13 | B26: 賞与健康被保険者 | C26: syoyo_health_insured_person | D26: tinyint | J26: コードマスタ.SQS0073
A27: 14 | B27: 賞与健康事業主 | C27: syoyo_health_business_owner | D27: tinyint | J27: コードマスタ.SQS0073
A28: 15 | B28: 賞与介護被保険者 | C28: syoyo_care_insured_person | D28: tinyint | J28: コードマスタ.SQS0073
A29: 16 | B29: 賞与介護事業主 | C29: syoyo_care_business_owner | D29: tinyint | J29: コードマスタ.SQS0073
... A41: 28 | B41: 賞与健康事業主(特定) | C41: syoyo_health_business_owner_specific | D41: tinyint | J41: コードマスタ.SQS0073
A42: 29 | B42: 作成者 | C42: created_by | D42: bigint | F42: not null
A43: 30 | B43: 作成日時 | C43: created_at | D43: datetime | E43: 6 | F43: not null
A44: 31 | B44: 更新者 | C44: updated_by | D44: bigint | F44: not null
A45: 32 | B45: 更新日時 | C45: updated_at | D45: datetime | E45: 6 | F45: not null

Sheet 会社銀行
A1: テーブル情報
B2: システム名 | C2: SOCIA | E2: 作成者 | I2: ITSP | M2: テーブル一覧へ
B3: サブシステム名 | C3: 給与 | E3: 作成日 | I3: 2025-11-28
B4: スキーマ名 | E4: RDBMS | I4: MySQL
B5: 論理テーブル名 | C5: 会社銀行 | E5: ENGINE | I5: InnoDB
B6: 物理テーブル名 | C6: kaisya_bank | E6: CHARSET | I6: utf8mb4
B7: 備考
A12: カラム情報 | L12: 外部キー情報
A13: No | B13: 論理名 | C13: 物理名 | D13: データ型 | E13: Size | F13: Not Null | G13: PK | H13: UK | I13: デフォルト | J13: 備考 | L13: 親テーブル | M13: 参照カラム
A14: 1 | B14: 会社コード | C14: kaisyacd | D14: varchar | E14: 20 | F14: not null | G14: 〇
A15: 2 | B15: 届出コード | C15: submission_code | D15: varchar | E15: 20 | F15: not null | G15: 〇
A16: 3 | B16: 振込元銀行連番 | C16: remitter_bank_seq | D16: bigint | F16: not null | G16: 〇
A17: 4 | B17: 有効開始年月日 | C17: fromymd | D17: date | F17: not null | G17: 〇
A18: 5 | B18: 有効終了年月日 | C18: toymd | D18: date | F18: not null
A19: 6 | B19: 銀行コード | C19: bank_code | D19: varchar | E19: 20
A20: 7 | B20: 支店コード | C20: branch_code | D20: varchar | E20: 20
A21: 8 | B21: 口座種別区分 | C21: account_class_type | D21: tinyint | J21: コードマスタ.SQS0068
A22: 9 | B22: 口座番号 | C22: account_number | D22: bigint
A23: 10 | B23: 委託者コード | C23: client_code | D23: bigint
A24: 11 | B24: 作成者 | C24: created_by | D24: bigint | F24: not null
A25: 12 | B25: 作成日時 | C25: created_at | D25: datetime | E25: 6 | F25: not null
A26: 13 | B26: 更新者 | C26: updated_by | D26: bigint | F26: not null
A27: 14 | B27: 更新日時 | C27: updated_at | D27: datetime | E27: 6 | F27: not null

Sheet 会社雇用保険端数処理情報
A1: テーブル情報
B2: システム名 | C2: SOCIA | E2: 作成者 | I2: ITSP | M2: テーブル一覧へ
B3: サブシステム名 | C3: 給与 | E3: 作成日 | I3: 2025-11-28
B4: スキーマ名 | E4: RDBMS | I4: MySQL
B5: 論理テーブル名 | C5: 会社雇用保険端数処理情報 | E5: ENGINE | I5: InnoDB
B6: 物理テーブル名 | C6: kaisya_employment_insurance_fraction_process | E6: CHARSET | I6: utf8mb4
B7: 備考
A12: カラム情報 | L12: 外部キー情報
A13: No | B13: 論理名 | C13: 物理名 | D13: データ型 | E13: Size | F13: Not Null | G13: PK | H13: UK | I13: デフォルト | J13: 備考 | L13: 親テーブル | M13: 参照カラム
A14: 1 | B14: 会社コード | C14: kaisyacd | D14: varchar | E14: 20 | F14: not null | G14: 〇
A15: 2 | B15: 届出コード | C15: submission_code | D15: varchar | E15: 20 | F15: not null | G15: 〇
A16: 3 | B16: 有効開始年月日 | C16: fromymd | D16: date | F16: not null | G16: 〇
A17: 4 | B17: 有効終了年月日 | C17: toymd | D17: date | F17: not null
A18: 5 | B18: 雇用保険被保険者端数区分 | C18: employment_insurance_insured_person_fraction_type | D18: tinyint | J18: コードマスタ.SQS0074
A19: 6 | B19: 作成者 | C19: created_by | D19: bigint | F19: not null
A20: 7 | B20: 作成日時 | C20: created_at | D20: datetime | E20: 6 | F20: not null
A21: 8 | B21: 更新者 | C21: updated_by | D21: bigint | F21: not null
A22: 9 | B22: 更新日時 | C22: updated_at | D22: datetime | E22: 6 | F22: not null

Sheet 体系
A1: テーブル情報
B2: システム名 | C2: SOCIA | E2: 作成者 | I2: ITSP | M2: テーブル一覧へ
B3: サブシステム名 | C3: 給与 | E3: 作成日 | I3: 2025-11-28
B4: スキーマ名 | E4: RDBMS | I4: MySQL
B5: 論理テーブル名 | C5: 体系 | E5: ENGINE | I5: InnoDB
B6: 物理テーブル名 | C6: taikei | E6: CHARSET | I6: utf8mb4
B7: 備考
A12: カラム情報 | L12: 外部キー情報
A13: No | B13: 論理名 | C13: 物理名 | D13: データ型 | E13: Size | F13: Not Null | G13: PK | H13: UK | I13: デフォルト | J13: 備考 | L13: 親テーブル | M13: 参照カラム
A14: 1 | B14: 会社コード | C14: kaisyacd | D14: varchar | E14: 20 | F14: not null | G14: 〇
A15: 2 | B15: 支給区分 | C15: payment_type | D15: tinyint | F15: not null | G15: 〇 | J15: コードマスタ.SQS0013
A16: 3 | B16: 体系コード | C16: taikei_code | D16: varchar | E16: 20 | F16: not null | G16: 〇
A17: 4 | B17: 有効開始年月日 | C17: fromymd | D17: date | F17: not null | G17: 〇
A18: 5 | B18: 有効終了年月日 | C18: toymd | D18: date | F18: not null
A19: 6 | B19: 体系名称 | C19: taikei_name | D19: varchar | E19: 255 | F19: not null
A20: 7 | B20: 明細書出力月 | C20: statement_output_month | D20: tinyint
A21: 8 | B21: 税率区分 | C21: tax_rate_type | D21: tinyint | F21: not null | J21: コードマスタ.SQS0050
A22: 9 | B22: 年末調整項目 | C22: nencho_item | D22: varchar | E22: 20
A23: 10 | B23: 非表示フラグ | C23: hidden | D23: boolean | F23: not null
A24: 11 | B24: 備考 | C24: note | D24: text
A25: 12 | B25: 作成者 | C25: created_by | D25: bigint | F25: not null
A26: 13 | B26: 作成日時 | C26: created_at | D26: datetime | E26: 6 | F26: not null
A27: 14 | B27: 更新者 | C27: updated_by | D27: bigint | F27: not null
A28: 15 | B28: 更新日時 | C28: updated_at | D28: datetime | E28: 6 | F28: not null

Sheet 体系保険
A1: テーブル情報
B2: システム名 | C2: SOCIA | E2: 作成者 | I2: ITSP | M2: テーブル一覧へ
B3: サブシステム名 | C3: 給与 | E3: 作成日 | I3: 2025-11-28
B4: スキーマ名 | E4: RDBMS | I4: MySQL
B5: 論理テーブル名 | C5: 体系保険 | E5: ENGINE | I5: InnoDB
B6: 物理テーブル名 | C6: taikei_insurance | E6: CHARSET | I6: utf8mb4
B7: 備考
B8: 現行：QTISHOKENKOMOKU
A12: カラム情報 | L12: 外部キー情報
A13: No | B13: 論理名 | C13: 物理名 | D13: データ型 | E13: Size | F13: Not Null | G13: PK | H13: UK | I13: デフォルト | J13: 備考 | L13: 親テーブル | M13: 参照カラム
A14: 1 | B14: 会社コード | C14: kaisyacd | D14: varchar | E14: 20 | F14: not null | G14: 〇
A15: 2 | B15: 支給区分 | C15: payment_type | D15: tinyint | F15: not null | G15: 〇 | J15: コードマスタ.SQS0013
A16: 3 | B16: 体系コード | C16: taikei_code | D16: varchar | E16: 20 | F16: not null | G16: 〇
A17: 4 | B17: 体系項目コード | C17: taikei_item_code | D17: varchar | E17: 20 | F17: not null | G17: 〇
A18: 5 | B18: 保険区分 | C18: insurance_type | D18: tinyint | F18: not null | G18: 〇 | J18: コードマスタ.SQS0028
A19: 6 | B19: 保険会社コード | C19: insurance_kaisya_code | D19: varchar | E19: 20 | F19: not null | G19: 〇
A20: 7 | B20: 有効開始年月日 | C20: fromymd | D20: date | F20: not null | G20: 〇
A21: 8 | B21: 有効終了年月日 | C21: toymd | D21: date | F21: not null
A22: 9 | B22: 作成者 | C22: created_by | D22: bigint | F22: not null
A23: 10 | B23: 作成日時 | C23: created_at | D23: datetime | E23: 6 | F23: not null
A24: 11 | B24: 更新者 | C24: updated_by | D24: bigint | F24: not null
A25: 12 | B25: 更新日時 | C25: updated_at | D25: datetime | E25: 6 | F25: not null

Sheet 体系控除順
A1: テーブル情報
B2: システム名 | C2: SOCIA | E2: 作成者 | I2: ITSP | M2: テーブル一覧へ
B3: サブシステム名 | C3: 給与 | E3: 作成日 | I3: 2025-11-28
B4: スキーマ名 | E4: RDBMS | I4: MySQL
B5: 論理テーブル名 | C5: 体系控除順 | E5: ENGINE | I5: InnoDB
B6: 物理テーブル名 | C6: taikei_deduction_order | E6: CHARSET | I6: utf8mb4
B7: 備考
A12: カラム情報 | L12: 外部キー情報
A13: No | B13: 論理名 | C13: 物理名 | D13: データ型 | E13: Size | F13: Not Null | G13: PK | H13: UK | I13: デフォルト | J13: 備考 | L13: 親テーブル | M13: 参照カラム
A14: 1 | B14: 会社コード | C14: kaisyacd | D14: varchar | E14: 20 | F14: not null | G14: 〇
A15: 2 | B15: 支給区分 | C15: payment_type | D15: tinyint | F15: not null | G15: 〇 | J15: コードマスタ.SQS0013
A16: 3 | B16: 体系コード | C16: taikei_code | D16: varchar | E16: 20 | F16: not null | G16: 〇
A17: 4 | B17: 控除順 | C17: deduction_order | D17: smallint | F17: not null | G17: 〇
A18: 5 | B18: 有効開始年月日 | C18: fromymd | D18: date | F18: not null | G18: 〇
A19: 6 | B19: 有効終了年月日 | C19: toymd | D19: date | F19: not null
A20: 7 | B20: 控除項目コード | C20: deduction_item_code | D20: varchar | E20: 20 | F20: not null
A21: 8 | B21: 作成者 | C21: created_by | D21: bigint | F21: not null
A22: 9 | B22: 作成日時 | C22: created_at | D22: datetime | E22: 6 | F22: not null
A23: 10 | B23: 更新者 | C23: updated_by | D23: bigint | F23: not null
A24: 11 | B24: 更新日時 | C24: updated_at | D24: datetime | E24: 6 | F24: not null

Sheet 体系明細書
A1: テーブル情報
B2: システム名 | C2: SOCIA | E2: 作成者 | I2: ITSP | M2: テーブル一覧へ
B3: サブシステム名 | C3: 給与 | E3: 作成日 | I3: 2025-11-28
B4: スキーマ名 | E4: RDBMS | I4: MySQL
B5: 論理テーブル名 | C5: 体系明細書 | E5: ENGINE | I5: InnoDB
B6: 物理テーブル名 | C6: taikei_statement | E6: CHARSET | I6: utf8mb4
B7: 備考
A12: カラム情報 | L12: 外部キー情報
A13: No | B13: 論理名 | C13: 物理名 | D13: データ型 | E13: Size | F13: Not Null | G13: PK | H13: UK | I13: デフォルト | J13: 備考 | L13: 親テーブル | M13: 参照カラム
A14: 1 | B14: 会社コード | C14: kaisyacd | D14: varchar | E14: 20 | F14: not null | G14: 〇
A15: 2 | B15: 支給区分 | C15: payment_type | D15: tinyint | F15: not null | G15: 〇 | J15: コードマスタ.SQS0013
A16: 3 | B16: 体系コード | C16: taikei_code | D16: varchar | E16: 20 | F16: not null | G16: 〇
A17: 4 | B17: 明細書コード | C17: statement_code | D17: varchar | E17: 20 | F17: not null | G17: 〇
A18: 5 | B18: 列番号 | C18: columnno | D18: int | F18: not null | G18: 〇
A19: 6 | B19: 行番号 | C19: lineno | D19: int | F19: not null | G19: 〇
A20: 7 | B20: 有効開始年月日 | C20: fromymd | D20: date | F20: not null | G20: 〇
A21: 8 | B21: 有効終了年月日 | C21: toymd | D21: date | F21: not null
A22: 9 | B22: 体系項目コード | C22: taikei_item_code | D22: varchar | E22: 20 | F22: not null
A23: 10 | B23: 作成者 | C23: created_by | D23: bigint | F23: not null
A24: 11 | B24: 作成日時 | C24: created_at | D24: datetime | E24: 6 | F24: not null
A25: 12 | B25: 更新者 | C25: updated_by | D25: bigint | F25: not null
A26: 13 | B26: 更新日時 | C26: updated_at | D26: datetime | E26: 6 | F26: not null

Sheet 体系明細書基本
A1: テーブル情報
B2: システム名 | C2: SOCIA | E2: 作成者 | I2: ITSP | M2: テーブル一覧へ
B3: サブシステム名 | C3: 給与 | E3: 作成日 | I3: 2025-11-28
B4: スキーマ名 | E4: RDBMS | I4: MySQL
B5: 論理テーブル名 | C5: 体系明細書基本 | E5: ENGINE | I5: InnoDB
B6: 物理テーブル名 | C6: taikei_statement_basic | E6: CHARSET | I6: utf8mb4
B7: 備考
A12: カラム情報 | L12: 外部キー情報
A13: No | B13: 論理名 | C13: 物理名 | D13: データ型 | E13: Size | F13: Not Null | G13: PK | H13: UK | I13: デフォルト | J13: 備考 | L13: 親テーブル | M13: 参照カラム
A14: 1 | B14: 会社コード | C14: kaisyacd | D14: varchar | E14: 20 | F14: not null | G14: 〇
A15: 2 | B15: 支給区分 | C15: payment_type | D15: tinyint | F15: not null | G15: 〇 | J15: コードマスタ.SQS0013
A16: 3 | B16: 体系コード | C16: taikei_code | D16: varchar | E16: 20 | F16: not null | G16: 〇
A17: 4 | B17: 明細書コード | C17: statement_code | D17: varchar | E17: 20 | F17: not null | G17: 〇
A18: 5 | B18: 有効開始年月日 | C18: fromymd | D18: date | F18: not null | G18: 〇
A19: 6 | B19: 有効終了年月日 | C19: toymd | D19: date | F19: not null
A20: 7 | B20: 明細書名称 | C20: statement_name | D20: varchar | E20: 255 | F20: not null
A21: 8 | B21: タイトル | C21: title | D21: varchar | E21: 50
A22: 9 | B22: 項目1ラベル | C22: item1_label | D22: varchar | E22: 255
A23: 10 | B23: 項目1表示項目ID | C23: item1_dsp_itemid | D23: varchar | E23: 20
A24: 11 | B24: 項目1表示タイプ | C24: item1_dsp_type | D24: json | J24: {"code":true|false,"name":true|false,"shorname":true|false}
A25: 12 | B25: 項目2ラベル | C25: item2_label | D25: varchar | E25: 255
A26: 13 | B26: 項目2表示項目ID | C26: item2_dsp_itemid | D26: varchar | E26: 20
A27: 14 | B27: 項目2表示タイプ | C27: item2_dsp_type | D27: json | J27: {"code":true|false,"name":true|false,"shorname":true|false}
A28: 15 | B28: 明細レイアウトJSON | C28: detail_layout_json | D28: json | J28: {"laborNo": 7, "paymentNo" 8, "deductionNo":9, "totalNo":6}
A29: 16 | B29: 作成者 | C29: created_by | D29: bigint | F29: not null
A30: 17 | B30: 作成日時 | C30: created_at | D30: datetime | E30: 6 | F30: not null
A31: 18 | B31: 更新者 | C31: updated_by | D31: bigint | F31: not null
A32: 19 | B32: 更新日時 | C32: updated_at | D32: datetime | E32: 6 | F32: not null

Sheet 体系明細書条件
A1: テーブル情報
B2: システム名 | C2: SOCIA | E2: 作成者 | I2: ITSP | M2: テーブル一覧へ
B3: サブシステム名 | C3: 給与 | E3: 作成日 | I3: 2025-11-28
B4: スキーマ名 | E4: RDBMS | I4: MySQL
B5: 論理テーブル名 | C5: 体系明細書条件 | E5: ENGINE | I5: InnoDB
B6: 物理テーブル名 | C6: taikei_statement_condition | E6: CHARSET | I6: utf8mb4
B7: 備考
B8: ・就業の計算プロセス条件式と合わせる_x000D_ ・抽出条件だけ利用(計算条件不要)
A12: カラム情報 | L12: 外部キー情報
A13: No | B13: 論理名 | C13: 物理名 | D13: データ型 | E13: Size | F13: Not Null | G13: PK | H13: UK | I13: デフォルト | J13: 備考 | L13: 親テーブル | M13: 参照カラム
A14: 1 | B14: 会社コード | C14: kaisyacd | D14: varchar | E14: 20 | F14: not null | G14: 〇
A15: 2 | B15: 支給区分 | C15: payment_type | D15: tinyint | F15: not null | G15: 〇 | J15: コードマスタ.SQS0013
A16: 3 | B16: 体系コード | C16: taikei_code | D16: varchar | E16: 20 | F16: not null | G16: 〇
A17: 4 | B17: 明細書コード | C17: statement_code | D17: varchar | E17: 20 | F17: not null | G17: 〇
A18: 5 | B18: 有効開始年月日 | C18: fromymd | D18: date | F18: not null | G18: 〇
A19: 6 | B19: 有効終了年月日 | C19: toymd | D19: date | F19: not null
A20: 7 | B20: 表示用条件式 | C20: dsp_condition | D20: text
A21: 8 | B21: 実行用条件式 | C21: execute_condition | D21: text
A22: 9 | B22: 作成者 | C22: created_by | D22: bigint | F22: not null
A23: 10 | B23: 作成日時 | C23: created_at | D23: datetime | E23: 6 | F23: not null
A24: 11 | B24: 更新者 | C24: updated_by | D24: bigint | F24: not null
A25: 12 | B25: 更新日時 | C25: updated_at | D25: datetime | E25: 6 | F25: not null

Sheet 体系条件
A1: テーブル情報
B2: システム名 | C2: SOCIA | E2: 作成者 | I2: ITSP | M2: テーブル一覧へ
B3: サブシステム名 | C3: 給与 | E3: 作成日 | I3: 2025-11-28
B4: スキーマ名 | E4: RDBMS | I4: MySQL
B5: 論理テーブル名 | C5: 体系条件 | E5: ENGINE | I5: InnoDB
B6: 物理テーブル名 | C6: taikei_condition | E6: CHARSET | I6: utf8mb4
B7: 備考
B8: ・就業の計算プロセス条件式と合わせる_x000D_ ・抽出条件だけ利用(計算条件不要)
A12: カラム情報 | L12: 外部キー情報
A13: No | B13: 論理名 | C13: 物理名 | D13: データ型 | E13: Size | F13: Not Null | G13: PK | H13: UK | I13: デフォルト | J13: 備考 | L13: 親テーブル | M13: 参照カラム
A14: 1 | B14: 会社コード | C14: kaisyacd | D14: varchar | E14: 20 | F14: not null | G14: 〇
A15: 2 | B15: 支給区分 | C15: payment_type | D15: tinyint | F15: not null | G15: 〇 | J15: コードマスタ.SQS0013
A16: 3 | B16: 体系コード | C16: taikei_code | D16: varchar | E16: 20 | F16: not null | G16: 〇
A17: 4 | B17: 有効開始年月日 | C17: fromymd | D17: date | F17: not null | G17: 〇
A18: 5 | B18: 有効終了年月日 | C18: toymd | D18: date | F18: not null
A19: 6 | B19: 表示用条件式 | C19: dsp_condition | D19: text
A20: 7 | B20: 実行用条件式 | C20: execute_condition | D20: text
A21: 8 | B21: 作成者 | C21: created_by | D21: bigint | F21: not null
A22: 9 | B22: 作成日時 | C22: created_at | D22: datetime | E22: 6 | F22: not null
A23: 10 | B23: 更新者 | C23: updated_by | D23: bigint | F23: not null
A24: 11 | B24: 更新日時 | C24: updated_at | D24: datetime | E24: 6 | F24: not null

Sheet 体系締日
A1: テーブル情報
B2: システム名 | C2: SOCIA | E2: 作成者 | I2: ITSP | M2: テーブル一覧へ
B3: サブシステム名 | C3: 給与 | E3: 作成日 | I3: 2025-11-28
B4: スキーマ名 | E4: RDBMS | I4: MySQL
B5: 論理テーブル名 | C5: 体系締日 | E5: ENGINE | I5: InnoDB
B6: 物理テーブル名 | C6: taikei_shime_day | E6: CHARSET | I6: utf8mb4
B7: 備考
B8: # 238109 より、同じ締日・支給月区分、支給日で体系が異なるケースはない_x000D_ 会社コード、基準日の条件で、支給区分、締日・支給月区分、支給日のユニック制約が必要
A12: カラム情報 | L12: 外部キー情報
A13: No | B13: 論理名 | C13: 物理名 | D13: データ型 | E13: Size | F13: Not Null | G13: PK | H13: UK | I13: デフォルト | J13: 備考 | L13: 親テーブル | M13: 参照カラム
A14: 1 | B14: 会社コード | C14: kaisyacd | D14: varchar | E14: 20 | F14: not null | G14: 〇
A15: 2 | B15: 支給区分 | C15: payment_type | D15: tinyint | F15: not null | G15: 〇 | J15: コードマスタ.SQS0013
A16: 3 | B16: 体系コード | C16: taikei_code | D16: varchar | E16: 20 | F16: not null | G16: 〇
A17: 4 | B17: 締日コード | C17: shime_day_code | D17: varchar | E17: 20 | F17: not null | G17: 〇
A18: 5 | B18: 有効開始年月日 | C18: fromymd | D18: date | F18: not null | G18: 〇
A19: 6 | B19: 有効終了年月日 | C19: toymd | D19: date | F19: not null
A20: 7 | B20: 締日 | C20: shime_day | D20: tinyint | F20: not null
A21: 8 | B21: 支給月区分 | C21: payment_month_type | D21: tinyint | F21: not null | J21: コードマスタ.SQS0012
A22: 9 | B22: 支給日 | C22: payment_day | D22: tinyint | F22: not null
A23: 10 | B23: 非表示フラグ | C23: hidden | D23: boolean | F23: not null
A24: 11 | B24: 有給更新区分 | C24: paid_update_type | D24: tinyint
A25: 12 | B25: 備考 | C25: note | D25: text
